I'm sorry, but an uncaught exception occurred.

While running game code:
FileNotFoundError: [Errno 2] No such file or directory: '/home/deck/.renpy/launcher-4/persistent'

-- Full Traceback ------------------------------------------------------------

Full traceback:
  File "/home/deck/Desktop/Herve-VN-project/renpy-8.3.2-sdk/renpy/bootstrap.py", line 359, in bootstrap
    renpy.main.main()
  File "/home/deck/Desktop/Herve-VN-project/renpy-8.3.2-sdk/renpy/main.py", line 666, in main
    renpy.persistent.update(True)
  File "/home/deck/Desktop/Herve-VN-project/renpy-8.3.2-sdk/renpy/persistent.py", line 434, in update
    save()
  File "/home/deck/Desktop/Herve-VN-project/renpy-8.3.2-sdk/renpy/persistent.py", line 456, in save
    renpy.loadsave.location.save_persistent(compressed)
  File "/home/deck/Desktop/Herve-VN-project/renpy-8.3.2-sdk/renpy/savelocation.py", line 622, in save_persistent
    l.save_persistent(data)
  File "/home/deck/Desktop/Herve-VN-project/renpy-8.3.2-sdk/renpy/savelocation.py", line 430, in save_persistent
    safe_rename(fn_new, fn)
  File "/home/deck/Desktop/Herve-VN-project/renpy-8.3.2-sdk/renpy/loadsave.py", line 303, in safe_rename
    os.unlink(new)
FileNotFoundError: [Errno 2] No such file or directory: '/home/deck/.renpy/launcher-4/persistent'

Linux-6.5.0-valve22-1-neptune-65-g9a338ed8a75e-x86_64-with-glibc2.39 x86_64
Ren'Py 8.3.2.24090902
Ren'Py Launcher 8.3.2.24090902
Tue Nov 26 22:18:05 2024
