I'm sorry, but an uncaught exception occurred.

While running game code:
  File "game/script.rpy", line 7, in script call
    call story1
  File "game/story/script1.rpy", line 310, in script
    hero "So... ? How was it to follow me to work ?"
Exception: Sayer 'hero' is not defined.

-- Full Traceback ------------------------------------------------------------

Full traceback:
  File "game/script.rpy", line 7, in script call
    call story1
  File "game/story/script1.rpy", line 310, in script
    hero "So... ? How was it to follow me to work ?"
  File "/run/media/deck/SD512/Documents/Git/Herve-VN-project/renpy-8.3.2-sdk/renpy/ast.py", line 2573, in execute
    Say.execute(self)
  File "/run/media/deck/SD512/Documents/Git/Herve-VN-project/renpy-8.3.2-sdk/renpy/ast.py", line 575, in execute
    who = eval_who(self.who, self.who_fast)
  File "/run/media/deck/SD512/Documents/Git/Herve-VN-project/renpy-8.3.2-sdk/renpy/ast.py", line 464, in eval_who
    raise Exception("Sayer '%s' is not defined." % who)
Exception: Sayer 'hero' is not defined.

Linux-6.1.52-valve16-1-neptune-61-x86_64-with-glibc2.40 x86_64
Ren'Py 8.3.2.24090902
Hervé 1.0
Thu Nov 14 19:33:25 2024
